2018-05-15 10:08:36,567 utilFunction.py[line:68] ERROR HTTPConnectionPool(host='123.122.22.77', port=1999): Max retries exceeded with url: http://httpbin.org/ip (Caused by ConnectTimeoutError(<urllib3.connection.HTTPConnection object at 0x06256890>, 'Connection to 123.122.22.77 timed out. (connect timeout=10)'))
2018-05-15 10:09:29,003 utilFunction.py[line:68] ERROR HTTPConnectionPool(host='123.122.22.77', port=1999): Max retries exceeded with url: http://httpbin.org/ip (Caused by ConnectTimeoutError(<urllib3.connection.HTTPConnection object at 0x05307890>, 'Connection to 123.122.22.77 timed out. (connect timeout=10)'))
